<?xml version="1.0" encoding="utf-8"?>
<robot>
  <link
    name="base_link">
    <inertial>
      <origin
        xyz="-0.096576 0.093216 -0.5062"
        rpy="0 0 0" />
      <mass
        value="6.6524" />
      <inertia
        ixx="1.072"
        ixy="0.0014296"
        ixz="-0.066318"
        iyy="1.1363"
        iyz="0.0042533"
        izz="0.20948" />
    </inertial>
    <visual>
      <origin
        xyz="0 0 0"
        rpy="0 0 0" />
      <geometry>
        <mesh
          filename="package://gummi_base_$(env ROS_GUMMI_BASE)/meshes/base_link.STL" />
      </geometry>
      <material
        name="">
        <color
          rgba="0.79216 0.81961 0.93333 1" />
      </material>
    </visual>
    <collision>
      <origin
        xyz="0 0 0"
        rpy="0 0 0" />
      <geometry>
        <mesh
          filename="package://gummi_base_$(env ROS_GUMMI_BASE)/meshes/base_link.STL" />
      </geometry>
    </collision>
  </link>

  <!-- j1_Link -->
  <link
    name="shoulder_preroll">
    <inertial>
      <origin
        xyz="-3.1428E-06 -0.0073636 0.053528"
        rpy="0 0 0" />
      <mass
        value="0.42246" />
      <inertia
        ixx="0.0013384"
        ixy="6.4017E-08"
        ixz="6.2475E-08"
        iyy="0.0012663"
        iyz="0.00011953"
        izz="0.00092802" />
    </inertial>
    <visual>
      <origin
        xyz="0 0 0"
        rpy="0 0 0" />
      <geometry>
        <mesh
          filename="package://gummi_base_$(env ROS_GUMMI_BASE)/meshes/j1_Link.STL" />
      </geometry>
      <material
        name="">
        <color
          rgba="0.79216 0.81961 0.93333 1" />
      </material>
    </visual>
    <collision>
      <origin
        xyz="0 0 0"
        rpy="0 0 0" />
      <geometry>
        <mesh
          filename="package://gummi_base_$(env ROS_GUMMI_BASE)/meshes/j1_Link.STL" />
      </geometry>
    </collision>
  </link>

  <!-- j1 -->
  <joint
    name="shoulder_yaw"
    type="revolute">
    <origin
      xyz="0 0 0"
      rpy="0 0 0" />
    <parent
      link="base_link" />
    <child
      link="shoulder_preroll" />
    <axis
      xyz="0 0 1" />
    <!-- <limit
      lower="-1.5708"
      upper="1.5708"
      effort="0"
      velocity="0" /> -->
    <limit effort="0" lower="-0.75" upper="1.0" velocity="1.0"/>
  </joint>

  <!-- j2_Link -->
  <link
    name="shoulder">
    <inertial>
      <origin
        xyz="-7.4885E-05 -0.045317 5.3695E-06"
        rpy="0 0 0" />
      <mass
        value="0.29147" />
      <inertia
        ixx="0.00040953"
        ixy="-1.1184E-06"
        ixz="-1.4753E-06"
        iyy="0.00026628"
        iyz="5.6545E-08"
        izz="0.00048004" />
    </inertial>
    <visual>
      <origin
        xyz="0 0 0"
        rpy="0 0 0" />
      <geometry>
        <mesh
          filename="package://gummi_base_$(env ROS_GUMMI_BASE)/meshes/j2_Link.STL" />
      </geometry>
      <material
        name="">
        <color
          rgba="0.79216 0.81961 0.93333 1" />
      </material>
    </visual>
    <collision>
      <origin
        xyz="0 0 0"
        rpy="0 0 0" />
      <geometry>
        <mesh
          filename="package://gummi_base_$(env ROS_GUMMI_BASE)/meshes/j2_Link.STL" />
      </geometry>
    </collision>
  </link>

  <!-- j2 -->
  <joint
    name="shoulder_roll"
    type="revolute">
    <origin
      xyz="0 0 0.126"
      rpy="0 0 0" />
    <parent
      link="shoulder_preroll" />
    <child
      link="shoulder" />
    <axis
      xyz="0 -1 0" />
    <!-- <limit
      lower="-1.5708"
      upper="1.5708"
      effort="0"
      velocity="0" /> -->
    <limit effort="0" lower="-0.95" upper="2.3" velocity="1.0"/>
  </joint>

  <!-- j3_Link -->
  <link
    name="upperarm_preroll">
    <inertial>
      <origin
        xyz="-0.0021446 -0.0092567 -0.047728"
        rpy="0 0 0" />
      <mass
        value="0.10451" />
      <inertia
        ixx="5.4001E-05"
        ixy="5.1914E-07"
        ixz="-6.0861E-06"
        iyy="7.317E-05"
        iyz="-6.031E-07"
        izz="4.6633E-05" />
    </inertial>
    <visual>
      <origin
        xyz="0 0 0"
        rpy="0 0 0" />
      <geometry>
        <mesh
          filename="package://gummi_base_$(env ROS_GUMMI_BASE)/meshes/j3_Link.STL" />
      </geometry>
      <material
        name="">
        <color
          rgba="0.79216 0.81961 0.93333 1" />
      </material>
    </visual>
    <collision>
      <origin
        xyz="0 0 0"
        rpy="0 0 0" />
      <geometry>
        <mesh
          filename="package://gummi_base_$(env ROS_GUMMI_BASE)/meshes/j3_Link.STL" />
      </geometry>
    </collision>
  </link>

  <!-- j3 -->
  <joint
    name="shoulder_pitch"
    type="revolute">
    <origin
      xyz="0 -0.1185 0"
      rpy="0 0 0" />
    <parent
      link="shoulder" />
    <child
      link="upperarm_preroll" />
    <axis
      xyz="-1 0 0" />
<!-- <limit
      lower="-1.5708"
      upper="1.5708"
      effort="0"
      velocity="0" /> -->
    <limit effort="0" lower="-0.15" upper="1.1" velocity="1.0"/>
  </joint>

  <!-- j4_Link -->
  <link
    name="upperarm">
    <inertial>
      <origin
        xyz="-0.0024868 -9.272E-05 -0.088372"
        rpy="0 0 0" />
      <mass
        value="0.23537" />
      <inertia
        ixx="0.00067545"
        ixy="5.6472E-08"
        ixz="1.0957E-05"
        iyy="0.00067994"
        iyz="-1.7347E-06"
        izz="6.6647E-05" />
    </inertial>
    <visual>
      <origin
        xyz="0 0 0"
        rpy="0 0 0" />
      <geometry>
        <mesh
          filename="package://gummi_base_$(env ROS_GUMMI_BASE)/meshes/j4_Link.STL" />
      </geometry>
      <material
        name="">
        <color
          rgba="0.79216 0.81961 0.93333 1" />
      </material>
    </visual>
    <collision>
      <origin
        xyz="0 0 0"
        rpy="0 0 0" />
      <geometry>
        <mesh
          filename="package://gummi_base_$(env ROS_GUMMI_BASE)/meshes/j4_Link.STL" />
      </geometry>
    </collision>
  </link>

  <!-- j4 -->
  <joint
    name="upperarm_roll"
    type="revolute">
    <origin
      xyz="0.0135 -0.01 -0.081"
      rpy="0 0 0" />
    <parent
      link="upperarm_preroll" />
    <child
      link="upperarm" />
    <axis
      xyz="0 0 -1" />
    <!-- <limit
      lower="-1.5708"
      upper="1.5708"
      effort="0"
      velocity="0" /> -->
    <limit effort="0" lower="-1.56" upper="1.56" velocity="1.0"/>
  </joint>

  <!-- j5_Link -->
<link
  name="lowerarm_preroll_u">
  <inertial>
    <origin
      xyz="0.0480680914336555 -0.0154122894983864 -0.00982448117120333"
      rpy="0 0 0" />
    <mass
      value="0.0573776116734678" />
    <inertia
      ixx="1.98794332161084E-05"
      ixy="-1.22203388710061E-06"
      ixz="5.63209252093047E-06"
      iyy="4.47548061016055E-05"
      iyz="2.39819214170021E-07"
      izz="4.43764478788868E-05" />
  </inertial>
  <visual>
    <origin
      xyz="0 -.017 0"
      rpy="0 0 0" />
    <geometry>
      <mesh
        filename="package://gummi_base_$(env ROS_GUMMI_BASE)/meshes/j5_Link.STL" />
    </geometry>
    <material name="">
      <color rgba="1 0.7 0.7 1"/>
    </material>
  </visual>
  <collision>
    <origin
      xyz="0 -.017 0"
      rpy="0 0 0" />
    <geometry>
      <mesh
        filename="package://gummi_base_$(env ROS_GUMMI_BASE)/meshes/j5_Link.STL" />
    </geometry>
  </collision>
</link>

<!-- j5 -->
<joint
  name="elbow"
  type="revolute">
  <origin
    xyz="0 0.01475 -0.19105"
    rpy="0 0 0" />
  <parent
    link="upperarm" />
  <child
    link="lowerarm_preroll_u" />
  <axis
    xyz="0 -1 0" />
  <!-- <limit
    lower="-1.5708"
    upper="1.5708"
    effort="0"
    velocity="0" /> -->
  <limit effort="0" lower="-0.72" upper="0.32" velocity="1.0"/>
</joint>
</robot>
